Workbook

Sheet Problem Statement
A1: CPI data means Consumer Price Index data — it shows how much the prices of everyday goods and services have changed over time
A2: In India, the base year for the Consumer Price Index (CPI) is 2012.
A3: The National Statistical Office (NSO) releases CPI data every month.
A5: India CPI Inflation Case Study
A6: Overview: In India, the Consumer Price Index (CPI) is used to measure inflation, and it involves a fixed basket of goods and services. This basket is comprehensive and includes a wide array of items that an average Indian consumer uses. These items are not limited to just food and clothing but extend to transportation, medical care, electricity, education, and almost every other category that involves expenditure of money. The CPI is calculated by comparing the general price level in the markets during a particular time period with a base year. The items in the CPI basket are classified across various categories like food and beverages, clothing, housing, fuel and light, and recreation, among others.
A7: The CPI basket contains categories like food and beverages, housing, apparel, transportation, medical care, and more. The weight of each category in the total index might differ based on its relative importance to the average consumer expenditure but for the purpose of this analysis consider equal weights across all categories.
A9: The dataset provided is a CPI inflation index extracted from GOI website
A10: Each number represents the index value for that month and category
A11: There are missing values in the dataset – use suitable imputation technique (like moving averages), if required
A12: The CPI is an index and not a direct measure of price levels, but rather a relative indicator used to measure inflation or the average change in prices over time. Consumer Price Index (CPI) values cannot be summed across different months to derive meaningful insights or aggregate measures.
A13: CPI-U (Urban): Reflects spending patterns for urban consumers.
A14: CPI-R (Rural): Reflects spending patterns for rural consumers.
... A37: Identify trends in oil price change with change in inflation prices of all the categories and identify category whose inflation prices strongly changes with fluctuations in imported oil price (Hint: you can use =correl function)"

Sheet Given CPI Data
A1: Sector | B1: Year | C1: Month | D1: Cereals and products | E1: Meat and fish | F1: Egg | G1: Milk and products | H1: Oils and fats | I1: Fruits | J1: Vegetables | K1: Pulses and products | L1: Sugar and Confectionery | M1: Spices | N1: Non-alcoholic beverages | O1: Prepared meals, snacks, sweets etc. | P1: Food and beverages | Q1: Pan, tobacco and intoxicants | R1: Clothing | S1: Footwear | T1: Clothing and footwear | U1: Housing | V1: Fuel and light | W1: Household goods and services | X1: Health | Y1: Transport and communication | Z1: Recreation and amusement | AA1: Education | AB1: Personal care and effects | AC1: Miscellaneous | AD1: General index
A2: Rural | B2: 2013 | C2: January | D2: 107.5 | E2: 106.3 | F2: 108.1 | G2: 104.9 | H2: 106.1 | I2: 103.9 | J2: 101.9 | K2: 106.1 | L2: 106.8 | M2: 103.1 | N2: 104.8 | O2: 106.7 | P2: 105.5 | Q2: 105.1 | R2: 106.5 | S2: 105.8 | T2: 106.4 | U2: NA | V2: 105.5 | W2: 104.8 | X2: 104 | Y2: 103.3 | Z2: 103.4 | AA2: 103.8 | AB2: 104.7 | AC2: 104 | AD2: 105.1
A3: Urban | B3: 2013 | C3: January | D3: 110.5 | E3: 109.1 | F3: 113 | G3: 103.6 | H3: 103.4 | I3: 102.3 | J3: 102.9 | K3: 105.8 | L3: 105.1 | M3: 101.8 | N3: 105.1 | O3: 107.9 | P3: 105.9 | Q3: 105.2 | R3: 105.9 | S3: 105 | T3: 105.8 | U3: 100.3 | V3: 105.4 | W3: 104.8 | X3: 104.1 | Y3: 103.2 | Z3: 102.9 | AA3: 103.5 | AB3: 104.3 | AC3: 103.7 | AD3: 104
A4: Rural+Urban | B4: 2013 | C4: January | D4: 108.4 | E4: 107.3 | F4: 110 | G4: 104.4 | H4: 105.1 | I4: 103.2 | J4: 102.2 | K4: 106 | L4: 106.2 | M4: 102.7 | N4: 104.9 | O4: 107.3 | P4: 105.6 | Q4: 105.1 | R4: 106.3 | S4: 105.5 | T4: 106.2 | U4: 100.3 | V4: 105.5 | W4: 104.8 | X4: 104 | Y4: 103.2 | Z4: 103.1 | AA4: 103.6 | AB4: 104.5 | AC4: 103.9 | AD4: 104.6
A5: Rural | B5: 2013 | C5: February | D5: 109.2 | E5: 108.7 | F5: 110.2 | G5: 105.4 | H5: 106.7 | I5: 104 | J5: 102.4 | K5: 105.9 | L5: 105.7 | M5: 103.1 | N5: 105.1 | O5: 107.7 | P5: 106.3 | Q5: 105.6 | R5: 107.1 | S5: 106.3 | T5: 107 | U5: NA | V5: 106.2 | W5: 105.2 | X5: 104.4 | Y5: 103.9 | Z5: 104 | AA5: 104.1 | AB5: 104.6 | AC5: 104.4 | AD5: 105.8
A6: Urban | B6: 2013 | C6: February | D6: 112.9 | E6: 112.9 | F6: 116.9 | G6: 104 | H6: 103.5 | I6: 103.1 | J6: 104.9 | K6: 104.1 | L6: 103.8 | M6: 102.3 | N6: 106 | O6: 109 | P6: 107.2 | Q6: 106 | R6: 106.6 | S6: 105.5 | T6: 106.4 | U6: 100.4 | V6: 105.7 | W6: 105.2 | X6: 104.7 | Y6: 104.4 | Z6: 103.3 | AA6: 103.7 | AB6: 104.3 | AC6: 104.3 | AD6: 104.7
A7: Rural+Urban | B7: 2013 | C7: February | D7: 110.4 | E7: 110.2 | F7: 112.8 | G7: 104.9 | H7: 105.5 | I7: 103.6 | J7: 103.2 | K7: 105.3 | L7: 105.1 | M7: 102.8 | N7: 105.5 | O7: 108.3 | P7: 106.6 | Q7: 105.7 | R7: 106.9 | S7: 106 | T7: 106.8 | U7: 100.4 | V7: 106 | W7: 105.2 | X7: 104.5 | Y7: 104.2 | Z7: 103.6 | AA7: 103.9 | AB7: 104.5 | AC7: 104.4 | AD7: 105.3
A8: Rural | B8: 2013 | C8: March | D8: 110.2 | E8: 108.8 | F8: 109.9 | G8: 105.6 | H8: 106.2 | I8: 105.7 | J8: 101.4 | K8: 105.7 | L8: 105 | M8: 103.3 | N8: 105.6 | O8: 108.2 | P8: 106.6 | Q8: 106.5 | R8: 107.6 | S8: 106.8 | T8: 107.5 | U8: NA | V8: 106.1 | W8: 105.6 | X8: 104.7 | Y8: 104.6 | Z8: 104 | AA8: 104.3 | AB8: 104.3 | AC8: 104.6 | AD8: 106
A9: Urban | B9: 2013 | C9: March | D9: 113.9 | E9: 111.4 | F9: 113.2 | G9: 104.3 | H9: 102.7 | I9: 104.9 | J9: 103.8 | K9: 103.5 | L9: 102.6 | M9: 102.4 | N9: 107 | O9: 109.8 | P9: 107.3 | Q9: 106.8 | R9: 107.2 | S9: 106 | T9: 107 | U9: 100.4 | V9: 106 | W9: 105.7 | X9: 105.2 | Y9: 105.5 | Z9: 103.5 | AA9: 103.8 | AB9: 104.2 | AC9: 104.9 | AD9: 105
A10: Rural+Urban | B10: 2013 | C10: March | D10: 111.4 | E10: 109.7 | F10: 111.2 | G10: 105.1 | H10: 104.9 | I10: 105.3 | J10: 102.2 | K10: 105 | L10: 104.2 | M10: 103 | N10: 106.2 | O10: 108.9 | P10: 106.9 | Q10: 106.6 | R10: 107.4 | S10: 106.5 | T10: 107.3 | U10: 100.4 | V10: 106.1 | W10: 105.6 | X10: 104.9 | Y10: 105.1 | Z10: 103.7 | AA10: 104 | AB10: 104.3 | AC10: 104.7 | AD10: 105.5
A11: Rural | B11: 2013 | C11: April | D11: 110.2 | E11: 109.5 | F11: 106.9 | G11: 106.3 | H11: 105.7 | I11: 108.3 | J11: 103.4 | K11: 105.7 | L11: 104.2 | M11: 103.2 | N11: 106.5 | O11: 108.8 | P11: 107.1 | Q11: 107.1 | R11: 108.1 | S11: 107.4 | T11: 108 | U11: NA | V11: 106.5 | W11: 106.1 | X11: 105.1 | Y11: 104.4 | Z11: 104.5 | AA11: 104.8 | AB11: 102.7 | AC11: 104.6 | AD11: 106.4
A12: Urban | B12: 2013 | C12: April | D12: 114.6 | E12: 113.4 | F12: 106 | G12: 104.7 | H12: 102.1 | I12: 109.5 | J12: 109.7 | K12: 104.6 | L12: 102 | M12: 103.5 | N12: 108.2 | O12: 110.6 | P12: 108.8 | Q12: 108.5 | R12: 107.9 | S12: 106.4 | T12: 107.7 | U12: 100.5 | V12: 106.4 | W12: 106.5 | X12: 105.7 | Y12: 105 | Z12: 104 | AA12: 105.2 | AB12: 103.2 | AC12: 105.1 | AD12: 105.7
A13: Rural+Urban | B13: 2013 | C13: April | D13: 111.6 | E13: 110.9 | F13: 106.6 | G13: 105.7 | H13: 104.4 | I13: 108.9 | J13: 105.5 | K13: 105.3 | L13: 103.5 | M13: 103.3 | N13: 107.2 | O13: 109.6 | P13: 107.7 | Q13: 107.5 | R13: 108 | S13: 107 | T13: 107.9 | U13: 100.5 | V13: 106.5 | W13: 106.3 | X13: 105.3 | Y13: 104.7 | Z13: 104.2 | AA13: 105 | AB13: 102.9 | AC13: 104.8 | AD13: 106.1
A14: Rural | B14: 2013 | C14: May | D14: 110.9 | E14: 109.8 | F14: 105.9 | G14: 107.5 | H14: 105.3 | I14: 108.1 | J14: 107.3 | K14: 106.1 | L14: 103.7 | M14: 104 | N14: 107.4 | O14: 109.9 | P14: 108.1 | Q14: 108.1 | R14: 108.8 | S14: 107.9 | T14: 108.6 | U14: NA | V14: 107.5 | W14: 106.8 | X14: 105.7 | Y14: 104.1 | Z14: 105 | AA14: 105.5 | AB14: 102.1 | AC14: 104.8 | AD14: 107.2
A15: Urban | B15: 2013 | C15: May | D15: 115.4 | E15: 114.2 | F15: 102.7 | G15: 105.5 | H15: 101.5 | I15: 110.6 | J15: 123.7 | K15: 105.2 | L15: 101.9 | M15: 105 | N15: 109.1 | O15: 111.3 | P15: 111.1 | Q15: 109.8 | R15: 108.5 | S15: 106.7 | T15: 108.3 | U15: 100.5 | V15: 107.2 | W15: 107.1 | X15: 106.2 | Y15: 103.9 | Z15: 104.6 | AA15: 105.7 | AB15: 102.6 | AC15: 104.9 | AD15: 106.6
A16: Rural+Urban | B16: 2013 | C16: May | D16: 112.3 | E16: 111.3 | F16: 104.7 | G16: 106.8 | H16: 103.9 | I16: 109.3 | J16: 112.9 | K16: 105.8 | L16: 103.1 | M16: 104.3 | N16: 108.1 | O16: 110.5 | P16: 109.2 | Q16: 108.6 | R16: 108.7 | S16: 107.4 | T16: 108.5 | U16: 100.5 | V16: 107.4 | W16: 106.9 | X16: 105.9 | Y16: 104 | Z16: 104.8 | AA16: 105.6 | AB16: 102.3 | AC16: 104.8 | AD16: 106.9
A17: Rural | B17: 2013 | C17: June | D17: 112.3 | E17: 112.1 | F17: 108.1 | G17: 108.3 | H17: 105.9 | I17: 109.2 | J17: 118 | K17: 106.8 | L17: 104.1 | M17: 105.4 | N17: 108.2 | O17: 111 | P17: 110.6 | Q17: 109 | R17: 109.7 | S17: 108.8 | T17: 109.5 | U17: NA | V17: 108.5 | W17: 107.5 | X17: 106.3 | Y17: 105 | Z17: 105.6 | AA17: 106.5 | AB17: 102.5 | AC17: 105.5 | AD17: 108.9
A18: Urban | B18: 2013 | C18: June | D18: 117 | E18: 120.1 | F18: 112.5 | G18: 107.3 | H18: 101.3 | I18: 112.4 | J18: 143.6 | K18: 105.4 | L18: 101.4 | M18: 106.4 | N18: 110 | O18: 112.2 | P18: 115 | Q18: 110.9 | R18: 109.2 | S18: 107.2 | T18: 108.9 | U18: 106.6 | V18: 108 | W18: 107.7 | X18: 106.5 | Y18: 105.2 | Z18: 105.2 | AA18: 108.1 | AB18: 103.3 | AC18: 106.1 | AD18: 109.7
A19: Rural+Urban | B19: 2013 | C19: June | D19: 113.8 | E19: 114.9 | F19: 109.8 | G19: 107.9 | H19: 104.2 | I19: 110.7 | J19: 126.7 | K19: 106.3 | L19: 103.2 | M19: 105.7 | N19: 109 | O19: 111.6 | P19: 112.2 | Q19: 109.5 | R19: 109.5 | S19: 108.1 | T19: 109.3 | U19: 106.6 | V19: 108.3 | W19: 107.6 | X19: 106.4 | Y19: 105.1 | Z19: 105.4 | AA19: 107.4 | AB19: 102.8 | AC19: 105.8 | AD19: 109.3
A20: Rural | B20: 2013 | C20: July | D20: 113.4 | E20: 114.9 | F20: 110.5 | G20: 109.3 | H20: 106.2 | I20: 110.3 | J20: 129.2 | K20: 107.1 | L20: 104.3 | M20: 106.4 | N20: 109.1 | O20: 112.1 | P20: 113.1 | Q20: 109.8 | R20: 110.5 | S20: 109.5 | T20: 110.3 | U20: NA | V20: 109.5 | W20: 108.3 | X20: 106.9 | Y20: 106.8 | Z20: 106.4 | AA20: 107.8 | AB20: 102.5 | AC20: 106.5 | AD20: 110.7
A21: Urban | B21: 2013 | C21: July | D21: 117.8 | E21: 119.2 | F21: 114 | G21: 108.3 | H21: 101.1 | I21: 113.2 | J21: 160.9 | K21: 105.1 | L21: 101.3 | M21: 107.5 | N21: 110.4 | O21: 113.1 | P21: 117.5 | Q21: 111.7 | R21: 109.8 | S21: 107.8 | T21: 109.5 | U21: 107.7 | V21: 108.6 | W21: 108.1 | X21: 107.1 | Y21: 107.3 | Z21: 105.9 | AA21: 110.1 | AB21: 103.2 | AC21: 107.3 | AD21: 111.4
A22: Rural+Urban | B22: 2013 | C22: July | D22: 114.8 | E22: 116.4 | F22: 111.9 | G22: 108.9 | H22: 104.3 | I22: 111.7 | J22: 140 | K22: 106.4 | L22: 103.3 | M22: 106.8 | N22: 109.6 | O22: 112.6 | P22: 114.7 | Q22: 110.3 | R22: 110.2 | S22: 108.8 | T22: 110 | U22: 107.7 | V22: 109.2 | W22: 108.2 | X22: 107 | Y22: 107.1 | Z22: 106.1 | AA22: 109.1 | AB22: 102.8 | AC22: 106.9 | AD22: 111
A23: Rural | B23: 2013 | C23: August | D23: 114.3 | E23: 115.4 | F23: 111.1 | G23: 110 | H23: 106.4 | I23: 110.8 | J23: 138.9 | K23: 107.4 | L23: 104.1 | M23: 106.9 | N23: 109.7 | O23: 112.6 | P23: 114.9 | Q23: 110.7 | R23: 111.3 | S23: 110.2 | T23: 111.1 | U23: NA | V23: 109.9 | W23: 108.7 | X23: 107.5 | Y23: 107.8 | Z23: 106.8 | AA23: 108.7 | AB23: 105 | AC23: 107.5 | AD23: 112.1
A24: Urban | B24: 2013 | C24: August | D24: 118.3 | E24: 120.4 | F24: 112.7 | G24: 108.9 | H24: 101.1 | I24: 108.7 | J24: 177 | K24: 104.7 | L24: 101 | M24: 108.5 | N24: 110.9 | O24: 114.3 | P24: 119.6 | Q24: 112.4 | R24: 110.6 | S24: 108.3 | T24: 110.2 | U24: 108.9 | V24: 109.3 | W24: 108.7 | X24: 107.6 | Y24: 108.1 | Z24: 106.5 | AA24: 110.8 | AB24: 106 | AC24: 108.3 | AD24: 112.7
A25: Rural+Urban | B25: 2013 | C25: August | D25: 115.6 | E25: 117.2 | F25: 111.7 | G25: 109.6 | H25: 104.5 | I25: 109.8 | J25: 151.8 | K25: 106.5 | L25: 103.1 | M25: 107.4 | N25: 110.2 | O25: 113.4 | P25: 116.6 | Q25: 111.2 | R25: 111 | S25: 109.4 | T25: 110.7 | U25: 108.9 | V25: 109.7 | W25: 108.7 | X25: 107.5 | Y25: 108 | Z25: 106.6 | AA25: 109.9 | AB25: 105.4 | AC25: 107.9 | AD25: 112.4
A26: Rural | B26: 2013 | C26: September | D26: 115.4 | E26: 115.7 | F26: 111.7 | G26: 111 | H26: 107.4 | I26: 110.9 | J26: 154 | K26: 108.1 | L26: 104.2 | M26: 107.9 | N26: 110.4 | O26: 114 | P26: 117.8 | Q26: 111.7 | R26: 112.7 | S26: 111.4 | T26: 112.5 | U26: NA | V26: 111.1 | W26: 109.6 | X26: 108.3 | Y26: 109.3 | Z26: 107.7 | AA26: 109.8 | AB26: 106.7 | AC26: 108.7 | AD26: 114.2
A27: Urban | B27: 2013 | C27: September | D27: 118.6 | E27: 119.1 | F27: 113.2 | G27: 109.6 | H27: 101.7 | I27: 103.2 | J27: 174.3 | K27: 105.1 | L27: 100.8 | M27: 109.1 | N27: 111.1 | O27: 115.4 | P27: 119.2 | Q27: 112.9 | R27: 111.4 | S27: 109 | T27: 111.1 | U27: 109.7 | V27: 109.5 | W27: 109.6 | X27: 107.9 | Y27: 110.4 | Z27: 107.4 | AA27: 111.2 | AB27: 106.9 | AC27: 109.4 | AD27: 113.2
A28: Rural+Urban | B28: 2013 | C28: September | D28: 116.4 | E28: 116.9 | F28: 112.3 | G28: 110.5 | H28: 105.3 | I28: 107.3 | J28: 160.9 | K28: 107.1 | L28: 103.1 | M28: 108.3 | N28: 110.7 | O28: 114.6 | P28: 118.3 | Q28: 112 | R28: 112.2 | S28: 110.4 | T28: 111.9 | U28: 109.7 | V28: 110.5 | W28: 109.6 | X28: 108.1 | Y28: 109.9 | Z28: 107.5 | AA28: 110.6 | AB28: 106.8 | AC28: 109 | AD28: 113.7
A29: Rural | B29: 2013 | C29: October | D29: 116.3 | E29: 115.4 | F29: 112.6 | G29: 111.7 | H29: 107.7 | I29: 113.2 | J29: 164.9 | K29: 108.3 | L29: 103.9 | M29: 108.2 | N29: 111.1 | O29: 114.9 | P29: 119.8 | Q29: 112.2 | R29: 113.6 | S29: 112.3 | T29: 113.4 | U29: NA | V29: 111.6 | W29: 110.4 | X29: 108.9 | Y29: 109.3 | Z29: 108.3 | AA29: 110.2 | AB29: 107.5 | AC29: 109.1 | AD29: 115.5
A30: Urban | B30: 2013 | C30: October | D30: 118.9 | E30: 118.1 | F30: 114.5 | G30: 110.4 | H30: 102.3 | I30: 106.2 | J30: 183.5 | K30: 105.3 | L30: 100.2 | M30: 109.6 | N30: 111.4 | O30: 116 | P30: 120.8 | Q30: 113.5 | R30: 112.5 | S30: 109.7 | T30: 112 | U30: 110.5 | V30: 109.7 | W30: 110.2 | X30: 108.2 | Y30: 109.7 | Z30: 108 | AA30: 111.3 | AB30: 107.3 | AC30: 109.4 | AD30: 114
A31: Rural+Urban | B31: 2013 | C31: October | D31: 117.1 | E31: 116.3 | F31: 113.3 | G31: 111.2 | H31: 105.7 | I31: 109.9 | J31: 171.2 | K31: 107.3 | L31: 102.7 | M31: 108.7 | N31: 111.2 | O31: 115.4 | P31: 120.2 | Q31: 112.5 | R31: 113.2 | S31: 111.2 | T31: 112.8 | U31: 110.5 | V31: 110.9 | W31: 110.3 | X31: 108.6 | Y31: 109.5 | Z31: 108.1 | AA31: 110.8 | AB31: 107.4 | AC31: 109.2 | AD31: 114.8
A32: Rural | B32: 2013 | C32: November | D32: 117.3 | E32: 114.9 | F32: 116.2 | G32: 112.8 | H32: 108.9 | I32: 116.6 | J32: 178.1 | K32: 109.1 | L32: 103.6 | M32: 109 | N32: 111.8 | O32: 116 | P32: 122.5 | Q32: 112.8 | R32: 114.6 | S32: 113.1 | T32: 114.4 | U32: NA | V32: 112.6 | W32: 111.3 | X32: 109.7 | Y32: 109.6 | Z32: 108.7 | AA32: 111 | AB32: 108.2 | AC32: 109.8 | AD32: 117.4
A33: Urban | B33: 2013 | C33: November | D33: 119.8 | E33: 116.3 | F33: 122.6 | G33: 112 | H33: 103.2 | I33: 110 | J33: 192.8 | K33: 106.3 | L33: 99.5 | M33: 110.3 | N33: 111.8 | O33: 117.1 | P33: 122.9 | Q33: 114.1 | R33: 113.5 | S33: 110.3 | T33: 113 | U33: 111.1 | V33: 110 | W33: 110.9 | X33: 108.6 | Y33: 109.5 | Z33: 108.5 | AA33: 111.3 | AB33: 107.9 | AC33: 109.6 | AD33: 115
A34: Rural+Urban | B34: 2013 | C34: November | D34: 118.1 | E34: 115.4 | F34: 118.7 | G34: 112.5 | H34: 106.8 | I34: 113.5 | J34: 183.1 | K34: 108.2 | L34: 102.2 | M34: 109.4 | N34: 111.8 | O34: 116.5 | P34: 122.6 | Q34: 113.1 | R34: 114.2 | S34: 111.9 | T34: 113.8 | U34: 111.1 | V34: 111.6 | W34: 111.1 | X34: 109.3 | Y34: 109.5 | Z34: 108.6 | AA34: 111.2 | AB34: 108.1 | AC34: 109.7 | AD34: 116.3
A35: Rural | B35: 2013 | C35: December | D35: 118.4 | E35: 115.9 | F35: 120.4 | G35: 113.8 | H35: 109.5 | I35: 115.5 | J35: 145.7 | K35: 109.5 | L35: 102.9 | M35: 109.8 | N35: 112.1 | O35: 116.8 | P35: 118.7 | Q35: 113.6 | R35: 115.8 | S35: 114 | T35: 115.5 | U35: NA | V35: 112.8 | W35: 112.1 | X35: 110.1 | Y35: 109.9 | Z35: 109.2 | AA35: 111.6 | AB35: 108.1 | AC35: 110.1 | AD35: 115.5
A36: Urban | B36: 2013 | C36: December | D36: 120.5 | E36: 118.1 | F36: 128.5 | G36: 112.8 | H36: 103.4 | I36: 110.7 | J36: 144.8 | K36: 107.1 | L36: 98.6 | M36: 111.9 | N36: 112.1 | O36: 118.1 | P36: 117.8 | Q36: 115 | R36: 114.2 | S36: 110.9 | T36: 113.7 | U36: 110.7 | V36: 110.4 | W36: 111.3 | X36: 109 | Y36: 109.7 | Z36: 108.9 | AA36: 111.4 | AB36: 107.7 | AC36: 109.8 | AD36: 113.3
A37: Rural+Urban | B37: 2013 | C37: December | D37: 119.1 | E37: 116.7 | F37: 123.5 | G37: 113.4 | H37: 107.3 | I37: 113.3 | J37: 145.4 | K37: 108.7 | L37: 101.5 | M37: 110.5 | N37: 112.1 | O37: 117.4 | P37: 118.4 | Q37: 114 | R37: 115.2 | S37: 112.7 | T37: 114.8 | U37: 110.7 | V37: 111.9 | W37: 111.7 | X37: 109.7 | Y37: 109.8 | Z37: 109 | AA37: 111.5 | AB37: 107.9 | AC37: 110 | AD37: 114.5
A38: Rural | B38: 2014 | C38: January | D38: 118.9 | E38: 117.1 | F38: 120.5 | G38: 114.4 | H38: 109 | I38: 115.5 | J38: 123.9 | K38: 109.6 | L38: 101.8 | M38: 110.2 | N38: 112.4 | O38: 117.3 | P38: 116 | Q38: 114 | R38: 116.5 | S38: 114.5 | T38: 116.2 | U38: NA | V38: 113 | W38: 112.6 | X38: 110.6 | Y38: 110.5 | Z38: 109.6 | AA38: 111.8 | AB38: 108.3 | AC38: 110.6 | AD38: 114.2
A39: Urban | B39: 2014 | C39: January | D39: 121.2 | E39: 122 | F39: 129.9 | G39: 113.6 | H39: 102.9 | I39: 112.1 | J39: 118.9 | K39: 107.5 | L39: 96.9 | M39: 112.7 | N39: 112.1 | O39: 119 | P39: 115.5 | Q39: 115.7 | R39: 114.8 | S39: 111.3 | T39: 114.3 | U39: 111.6 | V39: 111 | W39: 111.9 | X39: 109.7 | Y39: 110.8 | Z39: 109.8 | AA39: 111.5 | AB39: 108 | AC39: 110.5 | AD39: 112.9
A40: Rural+Urban | B40: 2014 | C40: January | D40: 119.6 | E40: 118.8 | F40: 124.1 | G40: 114.1 | H40: 106.8 | I40: 113.9 | J40: 122.2 | K40: 108.9 | L40: 100.2 | M40: 111 | N40: 112.3 | O40: 118.1 | P40: 115.8 | Q40: 114.5 | R40: 115.8 | S40: 113.2 | T40: 115.4 | U40: 111.6 | V40: 112.2 | W40: 112.3 | X40: 110.3 | Y40: 110.7 | Z40: 109.7 | AA40: 111.6 | AB40: 108.2 | AC40: 110.6 | AD40: 113.6
...

Sheet BROADER INDEX
A1: Sector | B1: Year | C1: Month | D1: Food And Beverages | E1: Pan, tobacco and intoxicants | F1: Clothing And Footwear | G1: Housing | H1: Fuel and light | I1: Household goods and services | J1: Miscellaneous | K1: General index
A2: Rural | B2: 2013 | C2: January | D2: 105.51538 | E2: 105.1 | F2: 106.23333 | G2: ="" | H2: 105.5 | I2: 104.8 | J2: 103.86667 | K2: 105.1
A3: Urban | B3: 2013 | C3: January | D3: 105.87692 | E3: 105.2 | F3: 105.56667 | G3: 100.3 | H3: 105.4 | I3: 104.8 | J3: 103.61667 | K3: 104
A4: Rural+Urban | B4: 2013 | C4: January | D4: 105.63846 | E4: 105.1 | F4: 106 | G4: 100.3 | H4: 105.5 | I4: 104.8 | J4: 103.71667 | K4: 104.6
A5: Rural | B5: 2013 | C5: February | D5: 106.18462 | E5: 105.6 | F5: 106.8 | G5: ="" | H5: 106.2 | I5: 105.2 | J5: 104.23333 | K5: 105.8
A6: Urban | B6: 2013 | C6: February | D6: 106.96923 | E6: 106 | F6: 106.16667 | G6: 100.4 | H6: 105.7 | I6: 105.2 | J6: 104.11667 | K6: 104.7
A7: Rural+Urban | B7: 2013 | C7: February | D7: 106.47692 | E7: 105.7 | F7: 106.56667 | G7: 100.4 | H7: 106 | I7: 105.2 | J7: 104.18333 | K7: 105.3
A8: Rural | B8: 2013 | C8: March | D8: 106.32308 | E8: 106.5 | F8: 107.3 | G8: ="" | H8: 106.1 | I8: 105.6 | J8: 104.41667 | K8: 106
A9: Urban | B9: 2013 | C9: March | D9: 106.67692 | E9: 106.8 | F9: 106.73333 | G9: 100.4 | H9: 106 | I9: 105.7 | J9: 104.51667 | K9: 105
A10: Rural+Urban | B10: 2013 | C10: March | D10: 106.46154 | E10: 106.6 | F10: 107.06667 | G10: 100.4 | H10: 106.1 | I10: 105.6 | J10: 104.45 | K10: 105.5
A11: Rural | B11: 2013 | C11: April | D11: 106.6 | E11: 107.1 | F11: 107.83333 | G11: ="" | H11: 106.5 | I11: 106.1 | J11: 104.35 | K11: 106.4
A12: Urban | B12: 2013 | C12: April | D12: 107.51538 | E12: 108.5 | F12: 107.33333 | G12: 100.5 | H12: 106.4 | I12: 106.5 | J12: 104.7 | K12: 105.7
A13: Rural+Urban | B13: 2013 | C13: April | D13: 106.93846 | E13: 107.5 | F13: 107.63333 | G13: 100.5 | H13: 106.5 | I13: 106.3 | J13: 104.48333 | K13: 106.1
A14: Rural | B14: 2013 | C14: May | D14: 107.23077 | E14: 108.1 | F14: 108.43333 | G14: ="" | H14: 107.5 | I14: 106.8 | J14: 104.53333 | K14: 107.2
A15: Urban | B15: 2013 | C15: May | D15: 109.01538 | E15: 109.8 | F15: 107.83333 | G15: 100.5 | H15: 107.2 | I15: 107.1 | J15: 104.65 | K15: 106.6
A16: Rural+Urban | B16: 2013 | C16: May | D16: 107.86154 | E16: 108.6 | F16: 108.2 | G16: 100.5 | H16: 107.4 | I16: 106.9 | J16: 104.56667 | K16: 106.9
A17: Rural | B17: 2013 | C17: June | D17: 109.23077 | E17: 109 | F17: 109.33333 | G17: ="" | H17: 108.5 | I17: 107.5 | J17: 105.23333 | K17: 108.9
A18: Urban | B18: 2013 | C18: June | D18: 112.66154 | E18: 110.9 | F18: 108.43333 | G18: 106.6 | H18: 108 | I18: 107.7 | J18: 105.73333 | K18: 109.7
A19: Rural+Urban | B19: 2013 | C19: June | D19: 110.46154 | E19: 109.5 | F19: 108.96667 | G19: 106.6 | H19: 108.3 | I19: 107.6 | J19: 105.48333 | K19: 109.3
A20: Rural | B20: 2013 | C20: July | D20: 111.22308 | E20: 109.8 | F20: 110.1 | G20: ="" | H20: 109.5 | I20: 108.3 | J20: 106.15 | K20: 110.7
A21: Urban | B21: 2013 | C21: July | D21: 114.56923 | E21: 111.7 | F21: 109.03333 | G21: 107.7 | H21: 108.6 | I21: 108.1 | J21: 106.81667 | K21: 111.4
A22: Rural+Urban | B22: 2013 | C22: July | D22: 112.41538 | E22: 110.3 | F22: 109.66667 | G22: 107.7 | H22: 109.2 | I22: 108.2 | J22: 106.5 | K22: 111
A23: Rural | B23: 2013 | C23: August | D23: 112.5 | E23: 110.7 | F23: 110.86667 | G23: ="" | H23: 109.9 | I23: 108.7 | J23: 107.21667 | K23: 112.1
A24: Urban | B24: 2013 | C24: August | D24: 115.85385 | E24: 112.4 | F24: 109.7 | G24: 108.9 | H24: 109.3 | I24: 108.7 | J24: 107.88333 | K24: 112.7
A25: Rural+Urban | B25: 2013 | C25: August | D25: 113.64615 | E25: 111.2 | F25: 110.36667 | G25: 108.9 | H25: 109.7 | I25: 108.7 | J25: 107.55 | K25: 112.4
A26: Rural | B26: 2013 | C26: September | D26: 114.5 | E26: 111.7 | F26: 112.2 | G26: ="" | H26: 111.1 | I26: 109.6 | J26: 108.41667 | K26: 114.2
A27: Urban | B27: 2013 | C27: September | D27: 115.41538 | E27: 112.9 | F27: 110.5 | G27: 109.7 | H27: 109.5 | I27: 109.6 | J27: 108.86667 | K27: 113.2
A28: Rural+Urban | B28: 2013 | C28: September | D28: 114.74615 | E28: 112 | F28: 111.5 | G28: 109.7 | H28: 110.5 | I28: 109.6 | J28: 108.65 | K28: 113.7
A29: Rural | B29: 2013 | C29: October | D29: 116 | E29: 112.2 | F29: 113.1 | G29: ="" | H29: 111.6 | I29: 110.4 | J29: 108.88333 | K29: 115.5
A30: Urban | B30: 2013 | C30: October | D30: 116.70769 | E30: 113.5 | F30: 111.4 | G30: 110.5 | H30: 109.7 | I30: 110.2 | J30: 108.98333 | K30: 114
A31: Rural+Urban | B31: 2013 | C31: October | D31: 116.16923 | E31: 112.5 | F31: 112.4 | G31: 110.5 | H31: 110.9 | I31: 110.3 | J31: 108.93333 | K31: 114.8
A32: Rural | B32: 2013 | C32: November | D32: 118.21538 | E32: 112.8 | F32: 114.03333 | G32: ="" | H32: 112.6 | I32: 111.3 | J32: 109.5 | K32: 117.4
A33: Urban | B33: 2013 | C33: November | D33: 118.81538 | E33: 114.1 | F33: 112.26667 | G33: 111.1 | H33: 110 | I33: 110.9 | J33: 109.23333 | K33: 115
A34: Rural+Urban | B34: 2013 | C34: November | D34: 118.36923 | E34: 113.1 | F34: 113.3 | G34: 111.1 | H34: 111.6 | I34: 111.1 | J34: 109.4 | K34: 116.3
A35: Rural | B35: 2013 | C35: December | D35: 116.07692 | E35: 113.6 | F35: 115.1 | G35: ="" | H35: 112.8 | I35: 112.1 | J35: 109.83333 | K35: 115.5
A36: Urban | B36: 2013 | C36: December | D36: 115.72308 | E36: 115 | F36: 112.93333 | G36: 110.7 | H36: 110.4 | I36: 111.3 | J36: 109.41667 | K36: 113.3
A37: Rural+Urban | B37: 2013 | C37: December | D37: 115.94615 | E37: 114 | F37: 114.23333 | G37: 110.7 | H37: 111.9 | I37: 111.7 | J37: 109.65 | K37: 114.5
A38: Rural | B38: 2014 | C38: January | D38: 114.35385 | E38: 114 | F38: 115.73333 | G38: ="" | H38: 113 | I38: 112.6 | J38: 110.23333 | K38: 114.2
A39: Urban | B39: 2014 | C39: January | D39: 114.17692 | E39: 115.7 | F39: 113.46667 | G39: 111.6 | H39: 111 | I39: 111.9 | J39: 110.05 | K39: 112.9
A40: Rural+Urban | B40: 2014 | C40: January | D40: 114.29231 | E40: 114.5 | F40: 114.8 | G40: 111.6 | H40: 112.2 | I40: 112.3 | J40: 110.18333 | K40: 113.6
...

Sheet Problem 1
A1: 1️⃣ Find who contributes the most for the recent month i.e May 2023
A7: Category | B7: Average Total | C7: % Total
A8: Average of Pan, tobacco and intoxicants | B8: =AVERAGE('BROADER INDEX'!E371:E373) -> 201.7 | C8: =SUM(B8)/SUM($B$8:$B$14) -> 0.15842382
A9: Average of Clothing And Footwear | B9: =AVERAGE('BROADER INDEX'!F371:F373) -> 183.53333 | C9: =SUM(B9)/SUM($B$8:$B$14) -> 0.14415495
A10: Average of Fuel and light | B10: =AVERAGE('BROADER INDEX'!H371:H373) -> 182.9 | C10: =SUM(B10)/SUM($B$8:$B$14) -> 0.1436575
A11: Average of Food And Beverages | B11: =AVERAGE('BROADER INDEX'!D371:D373) -> 177.76154 | C11: =SUM(B11)/SUM($B$8:$B$14) -> 0.13962153
A12: Average of Miscellaneous | B12: =AVERAGE('BROADER INDEX'!J371:J373) -> 176.63889 | C12: =SUM(B12)/SUM($B$8:$B$14) -> 0.13873975
A13: Average of Housing | B13: =AVERAGE('BROADER INDEX'!G371:G373) -> 175.6 | C13: =SUM(B13)/SUM($B$8:$B$14) -> 0.13792377
A14: Average of Household goods and services | B14: =AVERAGE('BROADER INDEX'!I371:I373) -> 175.03333 | C14: =SUM(B14)/SUM($B$8:$B$14) -> 0.13747868

Sheet Problem 2
A1: 2️⃣ Check trend of inflation every year (2017 onwards), Year On Year Analysis.
A6: Year | B6: Average Of General Index | C6: Year On Year Growth
A7: 2017 | B7: 133.5 | C7: 0.0333
A8: 2018 | B8: 138.775 | C8: 0.0395
A9: 2019 | B9: 144.18182 | C9: 0.039
A10: 2020 | B10: 153.38 | C10: 0.0638
A11: 2021 | B11: 161.45833 | C11: 0.0527
A12: 2022 | B12: 172.15 | C12: 0.0662
A13: 2023 | B13: 177.62 | C13: 0.0318
A21: Year 2022 has the highest inflation rate because:
A23: 1. High food inflation
A24: Food (especially cereals, vegetables, and milk) saw sharp price increases during due to:
A25: Poor monsoons & heatwaves in parts of India → lower crop yields.
A26: Supply chain disruptions (higher transport costs, global shortages).
A27: Export restrictions (like on wheat and rice) tightened domestic supply, pushing up prices.
A29: 2. Energy & fuel costs
A30: 2022’s global commodity shock (Russia–Ukraine war) led to spikes in crude oil and fuel prices.
A31: Even though global crude eased later in 2022, pass-through into transport & logistics costs kept inflation elevated in early/mid 2023.
A33: 3. Imported inflation
A34: India is a large oil importer. A weak rupee during 2021–2022 made imports (fuel, edible oil, fertilizers) more expensive → sustained pressure on CPI.
A36: 4. Housing & services
... A42: In 2022, despite some easing in fuel, sticky food & services inflation kept averages at the peak.

Sheet Problem 3
A1: 3️⃣ Focus on food (for 12 months ending May 2023)
A5: Year | B5: Month | C5: Food And Bevrages | D5: Month On Month Change
A6: 2022 | B6: June | C6: 174.3 | D6: 0.0104
A7: 2022 | B7: July | C7: 174.62564 | D7: 0.0019
A8: 2022 | B8: August | C8: 174.83846 | D8: 0.0012
A9: 2022 | B9: September | C9: 175.77179 | D9: 0.0053
A10: 2022 | B10: October | C10: 177.02821 | D10: 0.0071
A11: 2022 | B11: November | C11: 176.89487 | D11: -0.0008
A12: 2022 | B12: December | C12: 175.80256 | D12: -0.0062
A13: 2023 | B13: January | C13: 176.56667 | D13: 0.0043
A14: 2023 | B14: February | C14: 175.58974 | D14: -0.0055
A15: 2023 | B15: March | C15: 175.6 | D15: 0.0001
A16: 2023 | B16: April | C16: 176.44872 | D16: 0.0048
A17: 2023 | B17: May | C17: 177.76154 | D17: 0.0074
A22: Row Labels | B22: Average of Cereals and products | C22: Average of Food and beverages | D22: Average of Prepared meals, snacks, sweets etc. | E22: Average of Non-alcoholic beverages | F22: Average of Spices | G22: Average of Sugar and Confectionery | H22: Average of Pulses and products | I22: Average of Vegetables | J22: Average of Fruits | K22: Average of Oils and fats | L22: Average of Milk and products | M22: Average of Egg | N22: Average of Meat and fish
A23: 2022
A24: May | B24: 154.56667 | C24: 173.86667 | D24: 182.6 | E24: 166.26667 | F24: 184.3 | G24: 119.93333 | H24: 164.6 | I24: 179.5 | J24: 171.16667 | K24: 200.6 | L24: 164.96667 | M24: 162.63333 | N24: 217.63333
A25: June | B25: 155.43333 | C25: 175.53333 | D25: 184.03333 | E25: 167.06667 | F25: 186.5 | G25: 120.13333 | H25: 164.16667 | I25: 187.03333 | J25: 169.86667 | K25: 199.2 | L25: 165.86667 | M25: 171.06667 | N25: 220
A26: July | B26: 157 | C26: 175.63333 | D26: 185.33333 | E26: 167.56667 | F26: 189.36667 | G26: 120.23333 | H26: 164.23333 | I26: 186.4 | J26: 174.43333 | K26: 194.26667 | L26: 166.66667 | M26: 175.36667 | N26: 213.63333
A27: August | B27: 160.63333 | C27: 176.86667 | D27: 186.4 | E27: 168.03333 | F27: 192.96667 | G27: 121.1 | H27: 167.2 | I27: 190.96667 | J27: 173.06667 | K27: 191 | L27: 168.13333 | M27: 169.36667 | N27: 207.16667
A28: September | B28: 163.76667 | C28: 178.36667 | D28: 187.53333 | E28: 168.63333 | F28: 196.66667 | G28: 121.83333 | H28: 169.1 | I28: 196.5 | J28: 165.76667 | K28: 187.36667 | L28: 169.76667 | M28: 169.86667 | N28: 209.86667
A29: October | B29: 165.43333 | C29: 180.1 | D29: 188.46667 | E29: 169.1 | F29: 199.3 | G29: 122.13333 | H29: 169.8 | I29: 204.36667 | J29: 163.9 | K29: 185.26667 | L29: 170.93333 | M29: 171.03333 | N29: 211.53333
A30: November | B30: 167.56667 | C30: 178.73333 | D30: 189.6 | E30: 169.63333 | F30: 202.13333 | G30: 122.33333 | H30: 170.56667 | I30: 186.73333 | J30: 160.8 | K30: 187.63333 | L30: 172.3 | M30: 181.6 | N30: 210
A31: December | B31: 169.4 | C31: 176.3 | D31: 190.43333 | E31: 170.2 | F31: 204.4 | G31: 122.03333 | H31: 170.86667 | I31: 162.93333 | J31: 158.06667 | K31: 187.16667 | L31: 173.63333 | M31: 190.4 | N31: 209.6
A32: 2023
A33: January | B33: 173.7 | C33: 177.06667 | D33: 191.33333 | E33: 170.66667 | F33: 207.73333 | G33: 121.36667 | H33: 170.93333 | I33: 157.36667 | J33: 158.36667 | K33: 185.93333 | L33: 174.7 | M33: 194.8 | N33: 211.4
A34: February | B34: 174.43333 | C34: 177.5 | D34: 193.16667 | E34: 171.6 | F34: 208.86667 | G34: 120.33333 | H34: 171.2 | I34: 156.46667 | J34: 169.6 | K34: 178.3 | L34: 177.4 | M34: 175.43333 | N34: 208.36667
A35: March | B35: 174.46667 | C35: 177.53333 | D35: 193.16667 | E35: 171.6 | F35: 208.86667 | G35: 120.33333 | H35: 171.26667 | I35: 156.53333 | J35: 169.6 | K35: 178.23333 | L35: 177.4 | M35: 175.43333 | N35: 208.36667
A36: April | B36: 173.96667 | C36: 178.5 | D36: 193.66667 | E36: 172.2 | F36: 212.06667 | G36: 121.6 | H36: 173.63333 | I36: 159.36667 | J36: 176.4 | K36: 174.03333 | L36: 178.46667 | M36: 169.96667 | N36: 209.96667
A37: May | B37: 173.86667 | C37: 179.66667 | D37: 194.33333 | E37: 172.66667 | F37: 216.96667 | G37: 122.93333 | H37: 175.8 | I37: 164.9 | J37: 172.33333 | K37: 169.23333 | L37: 179.5 | M37: 173.63333 | N37: 215.06667
A38: Grand Total | B38: 166.47949 | C38: 177.35897 | D38: 189.2359 | E38: 169.63333 | F38: 200.77949 | G38: 121.25385 | H38: 169.48974 | I38: 176.08205 | J38: 167.95128 | K38: 186.01795 | L38: 172.28718 | M38: 175.43077 | N38: 211.73846
A40: Meat And Fish are the biggest individual category contributor for the last 12 month period for the given CPI Data.

Sheet Problem 4
A1: 4️⃣ COVID-19 effect. (MAR_2020, Start)
A4: Row Labels | B4: Average of Food And Beverages | C4: Average of Miscellaneous | D4: Average of Housing | E4: Average Of Essentials | F4: Inflation%
A5: January | B5: 149.34359 | C5: 144.48889 | D5: 153.9 | E5: 149.24416 | F5: 0.0034
A6: February | B6: 147.12821 | C6: 144.78333 | D6: 154.8 | E6: 148.90385 | F6: -0.0023
A7: March | B7: 145.85897 | C7: 145.2 | D7: 154.5 | E7: 148.51966 | F7: -0.0026
A8: April | B8: 147.70303 | C8: 149.93333 | D8: 155.6 | E8: 151.07879 | F8: 0.0172
A9: May
A10: June | B10: 151.61026 | C10: 148.82222 | D10: 154.7 | E10: 151.71083 | F10: 0.0042
A11: July | B11: 151.61026 | C11: 148.82222 | D11: 154.7 | E11: 151.71083 | F11: 0
A12: August | B12: 153.81282 | C12: 150.25 | D12: 155.5 | E12: 153.18761 | F12: 0.0097
A13: September | B13: 154.76923 | C13: 151.33333 | D13: 156.3 | E13: 154.13419 | F13: 0.0062
A14: October | B14: 157.94103 | C14: 151.61111 | D14: 156.5 | E14: 155.35071 | F14: 0.0079
A15: November | B15: 161.50513 | C15: 152.06111 | D15: 158 | E15: 157.18875 | F15: 0.0118
A16: December | B16: 162.4359 | C16: 152.56667 | D16: 158.4 | E16: 157.80085 | F16: 0.0039

Sheet Problem 5
A1: 5️⃣ How Broader Index Prices React To Change In Price Of Oil.
A3: 2021-2023 Average Of Broader Cpi Baskets And Imported Crude Oil Data Table:
A5: Row Labels | B5: Average of Food And Beverages | C5: Average of Miscellaneous | D5: Average of Household goods and services | E5: Average of Fuel and light | F5: Average of Housing | G5: Average of Clothing And Footwear | H5: Average of Pan, tobacco and intoxicants | I5: Oil Price (USD/BBL)
A6: January | B6: 167.77094 | C6: 163.33704 | D6: 161.16667 | E6: 164.28889 | F6: 164.76667 | G6: 166.03704 | H6: 193.21111 | I6: 71.13
A7: February | B7: 166.44188 | C7: 164.48519 | D7: 162.12222 | E7: 166.5 | F7: 166.26667 | G7: 167.37778 | H7: 194.37778 | I7: 74.7
A8: March | B8: 166.98803 | C8: 164.99259 | D8: 162.56667 | E8: 168.08889 | F8: 166.23333 | G8: 168.12593 | H8: 194.64444 | I8: 81.866667
A9: April | B9: 168.68376 | C9: 166.20926 | D9: 163.3 | E9: 169.75556 | F9: 167.86667 | G9: 169.20741 | H9: 195.26667 | I9: 84.766667
A10: May | B10: 170.82308 | C10: 167.43519 | D10: 164.87778 | E10: 172.07778 | F10: 168.23333 | G10: 170.92963 | H10: 196.58889 | I10: 88.866667
A11: June | B11: 169.33846 | C11: 163.2 | D11: 160.43333 | E11: 167.6 | F11: 163.65 | G11: 165.46111 | H11: 193.5 | I11: 92.333333
A12: July | B12: 170.02051 | C12: 164.28056 | D12: 161.43333 | E12: 169.93333 | F12: 164.65 | G12: 166.55 | H12: 193.8 | I12: 96.6
A13: August | B13: 169.8641 | C13: 165.075 | D13: 162.76667 | E13: 170.45 | F13: 165.55 | G13: 167.97222 | H13: 194.36667 | I13: 95.583333
A14: September | B14: 170.36667 | C14: 165.45278 | D14: 163.36667 | E14: 170.91667 | F14: 165.8 | G14: 168.87222 | H14: 194.86667 | I14: 93.366667
A15: October | B15: 172.3359 | C15: 166.25 | D15: 164.25 | E15: 172.2 | F15: 167.4 | G15: 169.89444 | H15: 195.36667 | I15: 89.666667
A16: November | B16: 172.9859 | C16: 166.85278 | D16: 165.2 | E16: 172.38333 | F16: 168 | G16: 171.08333 | H16: 195.71667 | I16: 84.533333
A17: December | B17: 171.94487 | C17: 167.61944 | D17: 165.98333 | E17: 172.8 | F17: 167.05 | G17: 172.16111 | H17: 195.71667 | I17: 81.91
A20: Category | B20: Corelation | C20: Impact Of Oil Price
A21: Food And Beverages | B21: =CORREL(Table9[Average of Food And Beverages],Table9[Oil Price (USD/BBL)]) -> 0.4601381 | C21: Weak to Moderate Positive
A22: Miscellaneous | B22: =CORREL(Table9[Average of Miscellaneous],Table9[Oil Price (USD/BBL)]) -> 0.083054449 | C22: Very Weak Positive
A23: Household Goods And Services | B23: =CORREL(Table9[Average of Household goods and services],Table9[Oil Price (USD/BBL)]) -> 0.0022263501 | C23: No correlation
A24: Fuel And Light | B24: =CORREL(Table9[Average of Fuel and light],Table9[Oil Price (USD/BBL)]) -> 0.5469257 | C24: Moderate Positive
A25: Housing | B25: =CORREL(Table9[Average of Housing],Table9[Oil Price (USD/BBL)]) -> -0.15113249 | C25: Very Weak Negative
A26: Clothing And Footwear | B26: =CORREL(Table9[Average of Clothing And Footwear],Table9[Oil Price (USD/BBL)]) -> 0.003217183 | C26: No correlation
A27: Pan Tobacco And Intoxicants | B27: =CORREL(Table9[Average of Pan, tobacco and intoxicants],Table9[Oil Price (USD/BBL)]) -> 0.092191979 | C27: Very Weak Positive
A30: 0.9 to 1.0 (or -0.9 to -1.0) → Very strong
A32: 0.7 to 0.9 (or -0.7 to -0.9) → Strong
A34: 0.5 to 0.7 (or -0.5 to -0.7) → Moderate
A36: 0.3 to 0.5 (or -0.3 to -0.5) → Weak to moderate
A38: 0.0 to 0.3 (or 0 to -0.3) → Very weak or no correlation

Sheet Formulas Used
A1: MAJOR FORMULAS USED IN THIS PROJECT.
A4: Name | B4: Formula
A5: Average | B5: AVERAGE(number1, [number2], …)
A6: Monthly Inflation Rate | B6: ((CPI IN CURRENT MONTH- CPI IN PREVIOUS MONTH)/CPI IN PREVIOUS MONTH)*100
A7: Annual Inflation Rate | B7: ((CPI AT THE END OF YEAR/CPI AT THE START OF YEAR)/CPI AT THE START OF YEAR)*100
A10: CPI Broader Groups & Sub-Categories
A12: 1. Food and Beverages 🍞🥛
A13: Cereals & products
A14: Meat & fish
A15: Eggs
A16: Milk & products
A17: Oils & fats
A18: Fruits
A19: Vegetables
A20: Pulses & products
A21: Sugar & confectionery
A22: Non-alcoholic beverages
... A59: 👉 These seven major groups cover the full basket of goods and services that households typically consume. The weights of these categories differ for rural, urban, and combined CPI.
